Workbook

Sheet Report
A2: Financial KPI report — 28 metrics
A3: Company | B3: =IF(Inputs!B2<>"",Inputs!B2,"") -> Microsoft Corporation
A4: Fiscal year / currency | B4: =IF(ISNUMBER(Inputs!C3),Inputs!C3,"") -> 2025 | C4: =IF(Inputs!C4<>"",Inputs!C4,"") -> USD
A6: Metric | B6: Result | C6: Basis / units | D6: Input status at build | E6: Details at build
A7: Revenue growth YoY | B7: =IF(ISNUMBER(Calculations!B2),Calculations!B2,"") -> 0.14932156 | C7: Annual / FY-end basis | D7: OK | E7: Reported consolidated growth; acquisition effects are included, not organic growth.
A8: EBITDA margin | B8: =IF(ISNUMBER(Calculations!B3),Calculations!B3,"") -> 0.55560762 | C8: Annual / FY-end basis | D8: OK | E8: Uses approximate reconstructed operating EBITDA (rounded Notes 6/9). Not reported EBITDA; see Derivations.
A9: Net debt | B9: =IF(ISNUMBER(Calculations!B4),Calculations!B4,"") -> 12909000000 | C9: =IF(Inputs!C4<>"",Inputs!C4&", millions","") -> USD, millions | D9: OK | E9: Borrowing debt less cash equivalents only; excludes $64.323bn short-term investments and $46.172bn finance-lease liabilities.
A10: Net debt / EBITDA | B10: =IF(ISNUMBER(Calculations!B5),Calculations!B5,"") -> 0.082470868 | C10: Multiple | D10: OK | E10: Uses approximate reconstructed operating EBITDA (rounded Notes 6/9). Not reported EBITDA; see Derivations.
A11: ARR | B11: =IF(ISNUMBER(Calculations!B6),Calculations!B6,"") | C11: =IF(Inputs!C4<>"",Inputs!C4&", millions","") -> USD, millions | D11: MISSING_INPUTS | E11: Missing/unavailable inputs: monthly_recurring_revenue FY2025
A12: WACC | B12: =IF(ISNUMBER(Calculations!B7),Calculations!B7,"") | C12: Market weights / CAPM | D12: MISSING_INPUTS | E12: Missing/unavailable inputs: market_cap FY2025, pre_tax_cost_of_debt FY2025, risk_free_rate FY2025, equity_beta FY2025, equity_risk_premium FY2025, marginal_tax_rate FY2025
A13: Gross margin | B13: =IF(ISNUMBER(Calculations!B8),Calculations!B8,"") -> 0.68823742 | C13: Annual / FY-end basis | D13: OK | E13: Computed from compatible reported financial-statement inputs under the documented model convention.
A14: EBIT margin | B14: =IF(ISNUMBER(Calculations!B9),Calculations!B9,"") -> 0.45621956 | C14: Annual / FY-end basis | D14: OK | E14: Operating income is the selected operating-EBIT definition.
A15: Net profit margin | B15: =IF(ISNUMBER(Calculations!B10),Calculations!B10,"") -> 0.36146015 | C15: Annual / FY-end basis | D15: OK | E15: Computed from compatible reported financial-statement inputs under the documented model convention.
A16: Free cash flow | B16: =IF(ISNUMBER(Calculations!B11),Calculations!B11,"") -> 71611000000 | C16: =IF(Inputs!C4<>"",Inputs!C4&", millions","") -> USD, millions | D16: OK | E16: CFO less cash PP&E additions. Noncash finance-lease additions and acquisitions are excluded.
A17: FCF margin | B17: =IF(ISNUMBER(Calculations!B12),Calculations!B12,"") -> 0.2541885 | C17: Annual / FY-end basis | D17: OK | E17: Uses cash-PP&E FCF, not lease-adjusted FCFF/FCFE.
A18: Current ratio | B18: =IF(ISNUMBER(Calculations!B13),Calculations!B13,"") -> 1.3534464 | C18: Multiple | D18: OK | E18: Computed from compatible reported financial-statement inputs under the documented model convention.
A19: Quick ratio | B19: =IF(ISNUMBER(Calculations!B14),Calculations!B14,"") -> 1.3468042 | C19: Multiple | D19: OK | E19: Computed from compatible reported financial-statement inputs under the documented model convention.
A20: Interest coverage | B20: =IF(ISNUMBER(Calculations!B15),Calculations!B15,"") -> 53.890147 | C20: Multiple | D20: OK | E20: Operating income / reported interest expense; excludes capitalized interest from the denominator.
A21: Return on assets | B21: =IF(ISNUMBER(Calculations!B16),Calculations!B16,"") -> 0.18004784 | C21: Annual / FY-end basis | D21: OK | E21: Two-point average total assets at June 30, 2024 and 2025.
A22: Return on equity | B22: =IF(ISNUMBER(Calculations!B17),Calculations!B17,"") -> 0.33280824 | C22: Annual / FY-end basis | D22: OK | E22: Two-point average stockholders' equity at June 30, 2024 and 2025.
A23: Enterprise value (simplified) | B23: =IF(ISNUMBER(Calculations!B18),Calculations!B18,"") | C23: =IF(Inputs!C4<>"",Inputs!C4&", millions","") -> USD, millions | D23: MISSING_INPUTS | E23: Missing/unavailable inputs: market_cap FY2025
A24: EV / Revenue | B24: =IF(ISNUMBER(Calculations!B19),Calculations!B19,"") | C24: Multiple | D24: MISSING_INPUTS | E24: Missing/unavailable inputs: market_cap FY2025
A25: EV / EBITDA | B25: =IF(ISNUMBER(Calculations!B20),Calculations!B20,"") | C25: Multiple | D25: MISSING_INPUTS | E25: Missing/unavailable inputs: market_cap FY2025 Approximate reconstructed operating EBITDA: operating EBIT + separately disclosed depreciation + intangible amortization; rounded source components. Not reported EBITDA; no extra ROU add-back.
A26: P/E | B26: =IF(ISNUMBER(Calculations!B21),Calculations!B21,"") | C26: Multiple | D26: MISSING_INPUTS | E26: Missing/unavailable inputs: market_cap FY2025
A27: Revenue CAGR | B27: =IF(ISNUMBER(Calculations!B22),Calculations!B22,"") -> 0.15300469 | C27: Annual / FY-end basis | D27: OK | E27: FY2023–FY2025, two elapsed years; acquisition effects included.
A28: EBITDA CAGR | B28: =IF(ISNUMBER(Calculations!B23),Calculations!B23,"") -> 0.23864534 | C28: Annual / FY-end basis | D28: OK | E28: Uses approximate reconstructed operating EBITDA (rounded Notes 6/9). Not reported EBITDA; see Derivations.
A29: Net leverage change YoY | B29: =IF(ISNUMBER(Calculations!B24),Calculations!B24,"") -> -0.17492099 | C29: Change in turns | D29: OK | E29: Uses approximate reconstructed operating EBITDA (rounded Notes 6/9). Not reported EBITDA; see Derivations.
A30: Cash conversion (CFO / EBITDA) | B30: =IF(ISNUMBER(Calculations!B25),Calculations!B25,"") -> 0.86988909 | C30: Annual / FY-end basis | D30: OK | E30: Uses approximate reconstructed operating EBITDA (rounded Notes 6/9). Not reported EBITDA; see Derivations.
A31: Days sales outstanding | B31: =IF(ISNUMBER(Calculations!B26),Calculations!B26,"") -> 82.159463 | C31: 365-day convention | D31: OK | E31: Proxy: average current net receivables / total revenue x 365; credit sales unavailable.
A32: Days inventory outstanding | B32: =IF(ISNUMBER(Calculations!B27),Calculations!B27,"") -> 4.5380333 | C32: 365-day convention | D32: OK | E32: Proxy: average inventory / total cost of revenue x 365; service-heavy denominator.
A33: Days payable outstanding | B33: =IF(ISNUMBER(Calculations!B28),Calculations!B28,"") -> 103.3109 | C33: 365-day convention | D33: OK | E33: Coarse proxy: average total AP / cost of revenue x 365. AP includes capex; credit purchases unavailable.
A34: Cash conversion cycle (CCC) | B34: =IF(ISNUMBER(Calculations!B29),Calculations!B29,"") -> -16.613408 | C34: 365-day convention | D34: OK | E34: Arithmetic CCC under model proxies. Capex AP and service revenue limit economic comparability; negative does not prove superior cash management.
A37: Calculation state
B38: RECALCULATED
A40: Statuses describe imported data at build time. Rerun after editing inputs.
A41: CAGR: first to latest FY. ROA/ROE: average balances. Cash conversion: CFO / EBITDA.
A42: CCC: DSO + DIO - DPO; revenue and COGS are documented credit-sales/purchases proxies.
A44: Microsoft FY2025 | ebitda | 22/28 available | Historical June 30, 2025 inputs
A45: Approximate reconstructed operating EBITDA; rounded Notes 6/9 components. See Derivations.
A46: Borrowing debt excludes leases; cash excludes short-term investments; CCC uses coarse proxies.

Sheet Assumptions
A2: Explicit cost-of-capital assumptions
A4: Assumption | B4: Explicit FY-end value
A5: Market value of debt (millions) | B5: 40400000000
A6: Pre tax cost of debt
A7: Risk free rate
A8: Equity beta
A9: Equity risk premium
A10: Marginal tax rate
A12: Rates are fractions (0.04 = 4%). No assumptions are estimated.
A13: Market debt is explicit; reported/book debt is not substituted.
A14: WACC: two capital components, CAPM cost of equity.

Sheet Calculations
A1: Template-owned formulas. Money displayed in millions; days use a 365-day convention.
A2: Revenue growth YoY | B2: =IF(AND(ISNUMBER(Inputs!B7),ISNUMBER(Inputs!C7),Inputs!B7<>0),Inputs!C7/Inputs!B7-1,"") -> 0.14932156
A3: EBITDA margin | B3: =IF(AND(ISNUMBER(Inputs!C8),ISNUMBER(Inputs!C7),Inputs!C7<>0),Inputs!C8/Inputs!C7,"") -> 0.55560762
A4: Net debt | B4: =IF(AND(ISNUMBER(Inputs!C9),ISNUMBER(Inputs!C10)),Inputs!C9-Inputs!C10,"") -> 12909000000
A5: Net debt / EBITDA | B5: =IF(AND(ISNUMBER(Inputs!C9),ISNUMBER(Inputs!C10),ISNUMBER(Inputs!C8),Inputs!C8>0,ISNUMBER(Calculations!B4)),B4/Inputs!C8,"") -> 0.082470868
A6: ARR | B6: =IF(AND(ISNUMBER(Inputs!C30),Inputs!C30>=0),Inputs!C30*12,"")
A7: WACC | B7: =IF(AND(ISNUMBER(Inputs!C27),ISNUMBER(Assumptions!B5),ISNUMBER(Assumptions!B6),ISNUMBER(Assumptions!B7),ISNUMBER(Assumptions!B8),ISNUMBER(Assumptions!B9),ISNUMBER(Assumptions!B10),Inputs!C27>=0,Assumptions!B5>=0,SUM(Inputs!C27,Assumptions!B5)>0,Assumptions!B6>=0,Assumptions!B9>=0,Assumptions!B10>=0,Assumptions!B10<=1),Inputs!C27/SUM(Inputs!C27,Assumptions!B5)*(Assumptions!B7+Assumptions!B8*Assumptions!B9)+Assumptions!B5/SUM(Inputs!C27,Assumptions!B5)*Assumptions!B6*(1-Assumptions!B10),"")
A8: Gross margin | B8: =IF(AND(ISNUMBER(Inputs!C12),ISNUMBER(Inputs!C7),Inputs!C7>0),Inputs!C12/Inputs!C7,"") -> 0.68823742
A9: EBIT margin | B9: =IF(AND(ISNUMBER(Inputs!C13),ISNUMBER(Inputs!C7),Inputs!C7>0),Inputs!C13/Inputs!C7,"") -> 0.45621956
A10: Net profit margin | B10: =IF(AND(ISNUMBER(Inputs!C14),ISNUMBER(Inputs!C7),Inputs!C7>0),Inputs!C14/Inputs!C7,"") -> 0.36146015
A11: Free cash flow | B11: =IF(AND(ISNUMBER(Inputs!C17),ISNUMBER(Inputs!C18),Inputs!C18>=0),Inputs!C17-Inputs!C18,"") -> 71611000000
A12: FCF margin | B12: =IF(AND(ISNUMBER(Inputs!C17),ISNUMBER(Inputs!C18),ISNUMBER(Inputs!C7),Inputs!C18>=0,Inputs!C7>0,ISNUMBER(Calculations!B11)),Calculations!B11/Inputs!C7,"") -> 0.2541885
A13: Current ratio | B13: =IF(AND(ISNUMBER(Inputs!C22),ISNUMBER(Inputs!C23),Inputs!C22>=0,Inputs!C23>0),Inputs!C22/Inputs!C23,"") -> 1.3534464
A14: Quick ratio | B14: =IF(AND(ISNUMBER(Inputs!C22),ISNUMBER(Inputs!C24),ISNUMBER(Inputs!C23),Inputs!C22>=0,Inputs!C23>0,Inputs!C24>=0,Inputs!C24<=Inputs!C22),(Inputs!C22-Inputs!C24)/Inputs!C23,"") -> 1.3468042
A15: Interest coverage | B15: =IF(AND(ISNUMBER(Inputs!C13),ISNUMBER(Inputs!C15),Inputs!C15>0),Inputs!C13/Inputs!C15,"") -> 53.890147
A16: Return on assets | B16: =IF(AND(ISNUMBER(Inputs!C14),ISNUMBER(Inputs!B20),ISNUMBER(Inputs!C20),Inputs!B20>=0,Inputs!C20>=0,SUM(Inputs!B20,Inputs!C20)>0),Inputs!C14/AVERAGE(Inputs!B20,Inputs!C20),"") -> 0.18004784
A17: Return on equity | B17: =IF(AND(ISNUMBER(Inputs!C14),ISNUMBER(Inputs!B21),ISNUMBER(Inputs!C21),Inputs!B21>=0,Inputs!C21>=0,SUM(Inputs!B21,Inputs!C21)>0),Inputs!C14/AVERAGE(Inputs!B21,Inputs!C21),"") -> 0.33280824
A18: Enterprise value (simplified) | B18: =IF(AND(ISNUMBER(Inputs!C27),ISNUMBER(Inputs!C9),ISNUMBER(Inputs!C10),Inputs!C27>=0,Inputs!C9>=0,Inputs!C10>=0),Inputs!C27+Inputs!C9-Inputs!C10,"")
A19: EV / Revenue | B19: =IF(AND(ISNUMBER(Inputs!C27),ISNUMBER(Inputs!C9),ISNUMBER(Inputs!C10),ISNUMBER(Inputs!C7),Inputs!C27>=0,Inputs!C9>=0,Inputs!C10>=0,Inputs!C7>0,ISNUMBER(Calculations!B18)),Calculations!B18/Inputs!C7,"")
A20: EV / EBITDA | B20: =IF(AND(ISNUMBER(Inputs!C27),ISNUMBER(Inputs!C9),ISNUMBER(Inputs!C10),ISNUMBER(Inputs!C8),Inputs!C27>=0,Inputs!C9>=0,Inputs!C10>=0,Inputs!C8>0,ISNUMBER(Calculations!B18)),Calculations!B18/Inputs!C8,"")
A21: P/E | B21: =IF(AND(ISNUMBER(Inputs!C27),ISNUMBER(Inputs!C14),Inputs!C27>=0,Inputs!C14>0),Inputs!C27/Inputs!C14,"")
A22: Revenue CAGR | B22: =IF(AND(ISNUMBER(Inputs!D7),ISNUMBER(Inputs!C7),Inputs!D7>0,Inputs!C7>=0,ISNUMBER(Inputs!D3),ISNUMBER(Inputs!C3),Inputs!C3>Inputs!D3),(Inputs!C7/Inputs!D7)^(1/(Inputs!C3-Inputs!D3))-1,"") -> 0.15300469
A23: EBITDA CAGR | B23: =IF(AND(ISNUMBER(Inputs!D8),ISNUMBER(Inputs!C8),Inputs!D8>0,Inputs!C8>=0,ISNUMBER(Inputs!D3),ISNUMBER(Inputs!C3),Inputs!C3>Inputs!D3),(Inputs!C8/Inputs!D8)^(1/(Inputs!C3-Inputs!D3))-1,"") -> 0.23864534
A24: Net leverage change YoY | B24: =IF(AND(ISNUMBER(Inputs!B9),ISNUMBER(Inputs!C9),ISNUMBER(Inputs!B10),ISNUMBER(Inputs!C10),ISNUMBER(Inputs!B8),ISNUMBER(Inputs!C8),Inputs!B8>0,Inputs!C8>0,ISNUMBER(Calculations!B5)),B5-(Inputs!B9-Inputs!B10)/Inputs!B8,"") -> -0.17492099
A25: Cash conversion (CFO / EBITDA) | B25: =IF(AND(ISNUMBER(Inputs!C17),ISNUMBER(Inputs!C8),Inputs!C8>0),Inputs!C17/Inputs!C8,"") -> 0.86988909
A26: Days sales outstanding | B26: =IF(AND(ISNUMBER(Inputs!B25),ISNUMBER(Inputs!C25),ISNUMBER(Inputs!C7),Inputs!B25>=0,Inputs!C25>=0,Inputs!C7>0),AVERAGE(Inputs!B25,Inputs!C25)/Inputs!C7*365,"") -> 82.159463
A27: Days inventory outstanding | B27: =IF(AND(ISNUMBER(Inputs!B24),ISNUMBER(Inputs!C24),ISNUMBER(Inputs!C11),Inputs!B24>=0,Inputs!C24>=0,Inputs!C11>0),AVERAGE(Inputs!B24,Inputs!C24)/Inputs!C11*365,"") -> 4.5380333
A28: Days payable outstanding | B28: =IF(AND(ISNUMBER(Inputs!B26),ISNUMBER(Inputs!C26),ISNUMBER(Inputs!C11),Inputs!B26>=0,Inputs!C26>=0,Inputs!C11>0),AVERAGE(Inputs!B26,Inputs!C26)/Inputs!C11*365,"") -> 103.3109
A29: Cash conversion cycle (CCC) | B29: =IF(AND(ISNUMBER(Inputs!B25),ISNUMBER(Inputs!C25),ISNUMBER(Inputs!C7),ISNUMBER(Inputs!B24),ISNUMBER(Inputs!C24),ISNUMBER(Inputs!C11),ISNUMBER(Inputs!B26),ISNUMBER(Inputs!C26),Inputs!B25>=0,Inputs!C25>=0,Inputs!C7>0,Inputs!B24>=0,Inputs!C24>=0,Inputs!C11>0,Inputs!B26>=0,Inputs!C26>=0,ISNUMBER(Calculations!B26),ISNUMBER(Calculations!B27),ISNUMBER(Calculations!B28)),Calculations!B26+Calculations!B27-Calculations!B28,"") -> -16.613408
A32: Unavailable inputs or invalid denominators leave results blank; see Checks.

Sheet Inputs
A2: Company | B2: Microsoft Corporation
A3: Fiscal year | B3: 2024 | C3: 2025 | D3: 2023
A4: Currency | B4: =IF(C4<>"",C4,"") -> USD | C4: USD
A5: Company ID / scope | B5: msft | C5: consolidated
A6: Amounts shown in millions | B6: Previous FY | C6: Latest FY | D6: First FY (CAGR only)
A7: Revenue | B7: 245122000000 | C7: 281724000000 | D7: 211915000000
A8: EBITDA | B8: 129433000000 | C8: 156528000000 | D8: 102023000000
A9: Total debt | B9: 51630000000 | C9: 43151000000
A10: Cash and equivalents | B10: 18315000000 | C10: 30242000000
A11: Cost of goods sold | B11: 74114000000 | C11: 87831000000
A12: Gross profit | B12: 171008000000 | C12: 193893000000
A13: EBIT | B13: 109433000000 | C13: 128528000000
A14: Net income | B14: 88136000000 | C14: 101832000000
A15: Interest expense | B15: 2935000000 | C15: 2385000000
A16: Income tax expense | B16: 19651000000 | C16: 21795000000
A17: Operating cash flow | B17: 118548000000 | C17: 136162000000
A18: Capex (positive spending) | B18: 44477000000 | C18: 64551000000
A19: Dividends paid | B19: 21771000000 | C19: 24082000000
A20: Total assets | B20: 512163000000 | C20: 619003000000
... A26: Accounts payable | B26: 21996000000 | C26: 27724000000
A27: Market cap
A28: Share price
A29: Shares outstanding | B29: 7434000000 | C29: 7434000000
A30: Monthly recurring revenue (MRR)
A32: Flows: full FY. Balances and market values: same FY end.
A33: Fiscal year labels do not imply 31 December.
A34: Share price is per share; shares are counts. Other money is shown in millions.

Sheet Checks
A2: Validation issues
A4: Severity | B4: Code | C4: Metric | D4: Company ID | E4: Message | F4: Source
A5: warning | B5: MISSING_INPUTS | C5: arr | D5: msft | E5: Missing/unavailable inputs: monthly_recurring_revenue FY2025
A6: warning | B6: MISSING_INPUTS | C6: wacc | D6: msft | E6: Missing/unavailable inputs: market_cap FY2025, pre_tax_cost_of_debt FY2025, risk_free_rate FY2025, equity_beta FY2025, equity_risk_premium FY2025, marginal_tax_rate FY2025
A7: warning | B7: MISSING_INPUTS | C7: enterprise_value | D7: msft | E7: Missing/unavailable inputs: market_cap FY2025
A8: warning | B8: MISSING_INPUTS | C8: ev_to_revenue | D8: msft | E8: Missing/unavailable inputs: market_cap FY2025
A9: warning | B9: MISSING_INPUTS | C9: ev_to_ebitda | D9: msft | E9: Missing/unavailable inputs: market_cap FY2025
A10: warning | B10: MISSING_INPUTS | C10: price_to_earnings | D10: msft | E10: Missing/unavailable inputs: market_cap FY2025
A11: warning | B11: DERIVED_APPROXIMATE | C11: ebitda | D11: msft | E11: Approximate reconstructed operating EBITDA: operating EBIT + separately disclosed depreciation + intangible amortization; rounded source components. Not reported EBITDA; no extra ROU add-back.
A12: warning | B12: DERIVED_APPROXIMATE | C12: ebitda | D12: msft | E12: Approximate reconstructed operating EBITDA: operating EBIT + separately disclosed depreciation + intangible amortization; rounded source components. Not reported EBITDA; no extra ROU add-back.
A13: warning | B13: DERIVED_APPROXIMATE | C13: ebitda | D13: msft | E13: Approximate reconstructed operating EBITDA: operating EBIT + separately disclosed depreciation + intangible amortization; rounded source components. Not reported EBITDA; no extra ROU add-back.

Sheet Source_Map
A2: Source-to-cell lineage
A4: Source file | B4: Source sheet | C4: Source row | D4: Source column | E4: Locator | F4: Field | G4: Fiscal year | H4: Period | I4: Scope | J4: Currency | K4: Original value | L4: Original unit | M4: Normalized value | N4: Canonical unit | O4: Value status | P4: Destination | Q4: Dependent metrics
A5: /Users/leonidpofa/VSCodeHruchevoPY/quant/Excel_automation/research/microsoft_fy2025/financials.csv | C5: 2 | D5: accounts_payable | E5: row 2, column accounts_payable | F5: accounts_payable | G5: 2023 | H5: FY | I5: consolidated | J5: USD | L5: millions | N5: USD | O5: missing
A6: /Users/leonidpofa/VSCodeHruchevoPY/quant/Excel_automation/research/microsoft_fy2025/financials.csv | C6: 3 | D6: accounts_payable | E6: row 3, column accounts_payable | F6: accounts_payable | G6: 2024 | H6: FY | I6: consolidated | J6: USD | K6: 21996 | L6: millions | M6: 21996000000 | N6: USD | O6: reported | P6: Inputs!B26 | Q6: dpo, cash_conversion_cycle
A7: /Users/leonidpofa/VSCodeHruchevoPY/quant/Excel_automation/research/microsoft_fy2025/financials.csv | C7: 4 | D7: accounts_payable | E7: row 4, column accounts_payable | F7: accounts_payable | G7: 2025 | H7: FY | I7: consolidated | J7: USD | K7: 27724 | L7: millions | M7: 27724000000 | N7: USD | O7: reported | P7: Inputs!C26 | Q7: dpo, cash_conversion_cycle
A8: /Users/leonidpofa/VSCodeHruchevoPY/quant/Excel_automation/research/microsoft_fy2025/financials.csv | C8: 2 | D8: accounts_receivable | E8: row 2, column accounts_receivable | F8: accounts_receivable | G8: 2023 | H8: FY | I8: consolidated | J8: USD | L8: millions | N8: USD | O8: missing
A9: /Users/leonidpofa/VSCodeHruchevoPY/quant/Excel_automation/research/microsoft_fy2025/financials.csv | C9: 3 | D9: accounts_receivable | E9: row 3, column accounts_receivable | F9: accounts_receivable | G9: 2024 | H9: FY | I9: consolidated | J9: USD | K9: 56924 | L9: millions | M9: 56924000000 | N9: USD | O9: reported | P9: Inputs!B25 | Q9: dso, cash_conversion_cycle
A10: /Users/leonidpofa/VSCodeHruchevoPY/quant/Excel_automation/research/microsoft_fy2025/financials.csv | C10: 4 | D10: accounts_receivable | E10: row 4, column accounts_receivable | F10: accounts_receivable | G10: 2025 | H10: FY | I10: consolidated | J10: USD | K10: 69905 | L10: millions | M10: 69905000000 | N10: USD | O10: reported | P10: Inputs!C25 | Q10: dso, cash_conversion_cycle
A11: /Users/leonidpofa/VSCodeHruchevoPY/quant/Excel_automation/research/microsoft_fy2025/financials.csv | C11: 2 | D11: capex | E11: row 2, column capex | F11: capex | G11: 2023 | H11: FY | I11: consolidated | J11: USD | K11: 28107 | L11: millions | M11: 28107000000 | N11: USD | O11: reported
A12: /Users/leonidpofa/VSCodeHruchevoPY/quant/Excel_automation/research/microsoft_fy2025/financials.csv | C12: 3 | D12: capex | E12: row 3, column capex | F12: capex | G12: 2024 | H12: FY | I12: consolidated | J12: USD | K12: 44477 | L12: millions | M12: 44477000000 | N12: USD | O12: reported | P12: Inputs!B18
A13: /Users/leonidpofa/VSCodeHruchevoPY/quant/Excel_automation/research/microsoft_fy2025/financials.csv | C13: 4 | D13: capex | E13: row 4, column capex | F13: capex | G13: 2025 | H13: FY | I13: consolidated | J13: USD | K13: 64551 | L13: millions | M13: 64551000000 | N13: USD | O13: reported | P13: Inputs!C18 | Q13: free_cash_flow, fcf_margin
A14: /Users/leonidpofa/VSCodeHruchevoPY/quant/Excel_automation/research/microsoft_fy2025/financials.csv | C14: 2 | D14: cash_and_equivalents | E14: row 2, column cash_and_equivalents | F14: cash_and_equivalents | G14: 2023 | H14: FY | I14: consolidated | J14: USD | K14: 34704 | L14: millions | M14: 34704000000 | N14: USD | O14: reported
A15: /Users/leonidpofa/VSCodeHruchevoPY/quant/Excel_automation/research/microsoft_fy2025/financials.csv | C15: 3 | D15: cash_and_equivalents | E15: row 3, column cash_and_equivalents | F15: cash_and_equivalents | G15: 2024 | H15: FY | I15: consolidated | J15: USD | K15: 18315 | L15: millions | M15: 18315000000 | N15: USD | O15: reported | P15: Inputs!B10 | Q15: net_leverage_trend
A16: /Users/leonidpofa/VSCodeHruchevoPY/quant/Excel_automation/research/microsoft_fy2025/financials.csv | C16: 4 | D16: cash_and_equivalents | E16: row 4, column cash_and_equivalents | F16: cash_and_equivalents | G16: 2025 | H16: FY | I16: consolidated | J16: USD | K16: 30242 | L16: millions | M16: 30242000000 | N16: USD | O16: reported | P16: Inputs!C10 | Q16: net_debt, net_debt_to_ebitda, enterprise_value, ev_to_revenue, ev_to_ebitda, net_leverage_trend
A17: /Users/leonidpofa/VSCodeHruchevoPY/quant/Excel_automation/research/microsoft_fy2025/financials.csv | C17: 2 | D17: cash_flow_from_operations | E17: row 2, column cash_flow_from_operations | F17: cash_flow_from_operations | G17: 2023 | H17: FY | I17: consolidated | J17: USD | K17: 87582 | L17: millions | M17: 87582000000 | N17: USD | O17: reported
A18: /Users/leonidpofa/VSCodeHruchevoPY/quant/Excel_automation/research/microsoft_fy2025/financials.csv | C18: 3 | D18: cash_flow_from_operations | E18: row 3, column cash_flow_from_operations | F18: cash_flow_from_operations | G18: 2024 | H18: FY | I18: consolidated | J18: USD | K18: 118548 | L18: millions | M18: 118548000000 | N18: USD | O18: reported | P18: Inputs!B17
A19: /Users/leonidpofa/VSCodeHruchevoPY/quant/Excel_automation/research/microsoft_fy2025/financials.csv | C19: 4 | D19: cash_flow_from_operations | E19: row 4, column cash_flow_from_operations | F19: cash_flow_from_operations | G19: 2025 | H19: FY | I19: consolidated | J19: USD | K19: 136162 | L19: millions | M19: 136162000000 | N19: USD | O19: reported | P19: Inputs!C17 | Q19: free_cash_flow, fcf_margin, cash_conversion
A20: /Users/leonidpofa/VSCodeHruchevoPY/quant/Excel_automation/research/microsoft_fy2025/financials.csv | C20: 2 | D20: cogs | E20: row 2, column cogs | F20: cogs | G20: 2023 | H20: FY | I20: consolidated | J20: USD | K20: 65863 | L20: millions | M20: 65863000000 | N20: USD | O20: reported
A21: /Users/leonidpofa/VSCodeHruchevoPY/quant/Excel_automation/research/microsoft_fy2025/financials.csv | C21: 3 | D21: cogs | E21: row 3, column cogs | F21: cogs | G21: 2024 | H21: FY | I21: consolidated | J21: USD | K21: 74114 | L21: millions | M21: 74114000000 | N21: USD | O21: reported | P21: Inputs!B11
A22: /Users/leonidpofa/VSCodeHruchevoPY/quant/Excel_automation/research/microsoft_fy2025/financials.csv | C22: 4 | D22: cogs | E22: row 4, column cogs | F22: cogs | G22: 2025 | H22: FY | I22: consolidated | J22: USD | K22: 87831 | L22: millions | M22: 87831000000 | N22: USD | O22: reported | P22: Inputs!C11 | Q22: dio, dpo, cash_conversion_cycle
A23: /Users/leonidpofa/VSCodeHruchevoPY/quant/Excel_automation/research/microsoft_fy2025/financials.csv | C23: 2 | D23: current_assets | E23: row 2, column current_assets | F23: current_assets | G23: 2023 | H23: FY | I23: consolidated | J23: USD | L23: millions | N23: USD | O23: missing
A24: /Users/leonidpofa/VSCodeHruchevoPY/quant/Excel_automation/research/microsoft_fy2025/financials.csv | C24: 3 | D24: current_assets | E24: row 3, column current_assets | F24: current_assets | G24: 2024 | H24: FY | I24: consolidated | J24: USD | K24: 159734 | L24: millions | M24: 159734000000 | N24: USD | O24: reported | P24: Inputs!B22
A25: /Users/leonidpofa/VSCodeHruchevoPY/quant/Excel_automation/research/microsoft_fy2025/financials.csv | C25: 4 | D25: current_assets | E25: row 4, column current_assets | F25: current_assets | G25: 2025 | H25: FY | I25: consolidated | J25: USD | K25: 191131 | L25: millions | M25: 191131000000 | N25: USD | O25: reported | P25: Inputs!C22 | Q25: current_ratio, quick_ratio
A26: /Users/leonidpofa/VSCodeHruchevoPY/quant/Excel_automation/research/microsoft_fy2025/financials.csv | C26: 2 | D26: current_liabilities | E26: row 2, column current_liabilities | F26: current_liabilities | G26: 2023 | H26: FY | I26: consolidated | J26: USD | L26: millions | N26: USD | O26: missing
A27: /Users/leonidpofa/VSCodeHruchevoPY/quant/Excel_automation/research/microsoft_fy2025/financials.csv | C27: 3 | D27: current_liabilities | E27: row 3, column current_liabilities | F27: current_liabilities | G27: 2024 | H27: FY | I27: consolidated | J27: USD | K27: 125286 | L27: millions | M27: 125286000000 | N27: USD | O27: reported | P27: Inputs!B23
A28: /Users/leonidpofa/VSCodeHruchevoPY/quant/Excel_automation/research/microsoft_fy2025/financials.csv | C28: 4 | D28: current_liabilities | E28: row 4, column current_liabilities | F28: current_liabilities | G28: 2025 | H28: FY | I28: consolidated | J28: USD | K28: 141218 | L28: millions | M28: 141218000000 | N28: USD | O28: reported | P28: Inputs!C23 | Q28: current_ratio, quick_ratio
A29: /Users/leonidpofa/VSCodeHruchevoPY/quant/Excel_automation/research/microsoft_fy2025/financials.csv | C29: 2 | D29: dividends_paid | E29: row 2, column dividends_paid | F29: dividends_paid | G29: 2023 | H29: FY | I29: consolidated | J29: USD | K29: 19800 | L29: millions | M29: 19800000000 | N29: USD | O29: reported
A30: /Users/leonidpofa/VSCodeHruchevoPY/quant/Excel_automation/research/microsoft_fy2025/financials.csv | C30: 3 | D30: dividends_paid | E30: row 3, column dividends_paid | F30: dividends_paid | G30: 2024 | H30: FY | I30: consolidated | J30: USD | K30: 21771 | L30: millions | M30: 21771000000 | N30: USD | O30: reported | P30: Inputs!B19
A31: /Users/leonidpofa/VSCodeHruchevoPY/quant/Excel_automation/research/microsoft_fy2025/financials.csv | C31: 4 | D31: dividends_paid | E31: row 4, column dividends_paid | F31: dividends_paid | G31: 2025 | H31: FY | I31: consolidated | J31: USD | K31: 24082 | L31: millions | M31: 24082000000 | N31: USD | O31: reported | P31: Inputs!C19
A32: /Users/leonidpofa/VSCodeHruchevoPY/quant/Excel_automation/research/microsoft_fy2025/financials.csv | C32: 2 | D32: ebit | E32: row 2, column ebit | F32: ebit | G32: 2023 | H32: FY | I32: consolidated | J32: USD | K32: 88523 | L32: millions | M32: 88523000000 | N32: USD | O32: reported
A33: /Users/leonidpofa/VSCodeHruchevoPY/quant/Excel_automation/research/microsoft_fy2025/financials.csv | C33: 3 | D33: ebit | E33: row 3, column ebit | F33: ebit | G33: 2024 | H33: FY | I33: consolidated | J33: USD | K33: 109433 | L33: millions | M33: 109433000000 | N33: USD | O33: reported | P33: Inputs!B13
A34: /Users/leonidpofa/VSCodeHruchevoPY/quant/Excel_automation/research/microsoft_fy2025/financials.csv | C34: 4 | D34: ebit | E34: row 4, column ebit | F34: ebit | G34: 2025 | H34: FY | I34: consolidated | J34: USD | K34: 128528 | L34: millions | M34: 128528000000 | N34: USD | O34: reported | P34: Inputs!C13 | Q34: ebit_margin, interest_coverage
A35: /Users/leonidpofa/VSCodeHruchevoPY/quant/Excel_automation/research/microsoft_fy2025/financials.csv | C35: 2 | D35: ebit | E35: row 2, column ebit | F35: ebitda | G35: 2023 | H35: FY | I35: consolidated | J35: USD | K35: 88523 | L35: millions | M35: 102023000000.0 | N35: USD | O35: derived_approximate | P35: Inputs!D8 | Q35: ebitda_cagr
A36: /Users/leonidpofa/VSCodeHruchevoPY/quant/Excel_automation/research/microsoft_fy2025/raw/definition_notes_excerpts.txt | C36: 0 | E36: {'file': 'research/microsoft_fy2025/raw/definition_notes_excerpts.txt', 'line': 53, 'web_extracted_line': 1386} | F36: ebitda | G36: 2023 | H36: FY | I36: consolidated | J36: USD | K36: 11.0 | L36: billions | M36: 102023000000.0 | N36: USD | O36: derived_approximate | P36: Inputs!D8 | Q36: ebitda_cagr
A37: /Users/leonidpofa/VSCodeHruchevoPY/quant/Excel_automation/research/microsoft_fy2025/raw/official_report_excerpts.txt | C37: 0 | E37: {'file': 'research/microsoft_fy2025/raw/official_report_excerpts.txt', 'line': 194, 'web_extracted_line': 1476} | F37: ebitda | G37: 2023 | H37: FY | I37: consolidated | J37: USD | K37: 2.5 | L37: billions | M37: 102023000000.0 | N37: USD | O37: derived_approximate | P37: Inputs!D8 | Q37: ebitda_cagr
A38: /Users/leonidpofa/VSCodeHruchevoPY/quant/Excel_automation/research/microsoft_fy2025/financials.csv | C38: 3 | D38: ebit | E38: row 3, column ebit | F38: ebitda | G38: 2024 | H38: FY | I38: consolidated | J38: USD | K38: 109433 | L38: millions | M38: 129433000000.0 | N38: USD | O38: derived_approximate | P38: Inputs!B8 | Q38: net_leverage_trend
A39: /Users/leonidpofa/VSCodeHruchevoPY/quant/Excel_automation/research/microsoft_fy2025/raw/definition_notes_excerpts.txt | C39: 0 | E39: {'file': 'research/microsoft_fy2025/raw/definition_notes_excerpts.txt', 'line': 53, 'web_extracted_line': 1386} | F39: ebitda | G39: 2024 | H39: FY | I39: consolidated | J39: USD | K39: 15.2 | L39: billions | M39: 129433000000.0 | N39: USD | O39: derived_approximate | P39: Inputs!B8 | Q39: net_leverage_trend
A40: /Users/leonidpofa/VSCodeHruchevoPY/quant/Excel_automation/research/microsoft_fy2025/raw/official_report_excerpts.txt | C40: 0 | E40: {'file': 'research/microsoft_fy2025/raw/official_report_excerpts.txt', 'line': 194, 'web_extracted_line': 1476} | F40: ebitda | G40: 2024 | H40: FY | I40: consolidated | J40: USD | K40: 4.8 | L40: billions | M40: 129433000000.0 | N40: USD | O40: derived_approximate | P40: Inputs!B8 | Q40: net_leverage_trend
A41: /Users/leonidpofa/VSCodeHruchevoPY/quant/Excel_automation/research/microsoft_fy2025/financials.csv | C41: 4 | D41: ebit | E41: row 4, column ebit | F41: ebitda | G41: 2025 | H41: FY | I41: consolidated | J41: USD | K41: 128528 | L41: millions | M41: 156528000000.0 | N41: USD | O41: derived_approximate | P41: Inputs!C8 | Q41: ebitda_margin, net_debt_to_ebitda, ev_to_ebitda, ebitda_cagr, net_leverage_trend, cash_conversion
A42: /Users/leonidpofa/VSCodeHruchevoPY/quant/Excel_automation/research/microsoft_fy2025/raw/definition_notes_excerpts.txt | C42: 0 | E42: {'file': 'research/microsoft_fy2025/raw/definition_notes_excerpts.txt', 'line': 53, 'web_extracted_line': 1386} | F42: ebitda | G42: 2025 | H42: FY | I42: consolidated | J42: USD | K42: 22.0 | L42: billions | M42: 156528000000.0 | N42: USD | O42: derived_approximate | P42: Inputs!C8 | Q42: ebitda_margin, net_debt_to_ebitda, ev_to_ebitda, ebitda_cagr, net_leverage_trend, cash_conversion
...

Sheet Data_Dictionary
A1: Template version | B1: 2
A2: Metric definitions
A4: Metric ID | B4: Label | C4: Formula / definition | D4: Required fields | E4: Unit | F4: Implementation | G4: Limitations
A5: revenue_growth_yoy | B5: Revenue growth YoY | C5: Revenue FY / Revenue FY-1 - 1 | D5: revenue:previous, revenue:latest | E5: % | F5: implemented | G5: Consecutive comparable fiscal years; nonzero prior revenue.
A6: ebitda_margin | B6: EBITDA margin | C6: EBITDA / Revenue | D6: ebitda:latest, revenue:latest | E6: % | F6: implemented | G6: Same FY, scope and currency; nonzero revenue.
A7: net_debt | B7: Net debt | C7: Total debt - Cash and equivalents | D7: total_debt:latest, cash_and_equivalents:latest | E7: currency | F7: implemented | G7: Both balances at the same fiscal year end; negative net debt is allowed.
A8: net_debt_to_ebitda | B8: Net debt / EBITDA | C8: Net debt / EBITDA | D8: total_debt:latest, cash_and_equivalents:latest, ebitda:latest | E8: x | F8: implemented | G8: Positive annual EBITDA required.
A9: arr | B9: ARR | C9: Explicit fiscal-year-end MRR x 12 | D9: monthly_recurring_revenue:latest | E9: currency | F9: implemented | G9: Annualized recurring run rate, not recognized annual revenue. Input MRR explicitly excludes nonrecurring revenue.
A10: wacc | B10: WACC | C10: E/(E+D)*(Rf+beta*ERP) + D/(E+D)*Kd*(1-tax) | D10: market_cap:latest, market_value_debt:latest, pre_tax_cost_of_debt:latest, risk_free_rate:latest, equity_beta:latest, equity_risk_premium:latest, marginal_tax_rate:latest | E10: % | F10: implemented | G10: Two-component CAPM model; explicit market equity/debt at FY end. Rates are decimal fractions; no book-debt substitution or inferred assumptions.
A11: gross_margin | B11: Gross margin | C11: gross_profit / Revenue | D11: gross_profit:latest, revenue:latest | E11: % | F11: implemented | G11: Reported numerator and positive annual revenue; no inferred numerator.
A12: ebit_margin | B12: EBIT margin | C12: ebit / Revenue | D12: ebit:latest, revenue:latest | E12: % | F12: implemented | G12: Reported numerator and positive annual revenue; no inferred numerator.
A13: net_profit_margin | B13: Net profit margin | C13: net_income / Revenue | D13: net_income:latest, revenue:latest | E13: % | F13: implemented | G13: Reported numerator and positive annual revenue; no inferred numerator.
A14: free_cash_flow | B14: Free cash flow | C14: Operating cash flow - positive capex spending | D14: cash_flow_from_operations:latest, capex:latest | E14: currency | F14: implemented | G14: CFO less capex spending; this is not FCFF or FCFE.
A15: fcf_margin | B15: FCF margin | C15: Free cash flow / Revenue | D15: cash_flow_from_operations:latest, capex:latest, revenue:latest | E15: % | F15: implemented | G15: Same FY and CFO-minus-capex convention.
... A32: cash_conversion_cycle | B32: Cash conversion cycle (CCC) | C32: DSO + DIO - DPO | D32: accounts_receivable:previous, accounts_receivable:latest, revenue:latest, inventory:previous, inventory:latest, cogs:latest, accounts_payable:previous, accounts_payable:latest | E32: days | F32: implemented | G32: Inherits DSO/DIO/DPO conventions. Negative CCC is valid. This is a duration, separate from CFO/EBITDA.

Sheet Filing_Sources
A1: Microsoft Annual Report 2025 — upstream source ledger
A2: https://www.microsoft.com/investor/reports/ar25/
A3: FY | B3: Field | C3: Input value | D3: Unit | E3: Upstream status | F3: Transformation | G3: Source section / row | H3: Saved evidence locator | I3: Notes
A4: 2025 | B4: revenue | C4: 281724 | D4: USD millions | E4: reported | F4: identity | G4: Income Statements / Total revenue | H4: research/microsoft_fy2025/raw/official_report_excerpts.txt:21 (web L814)
A5: 2024 | B5: revenue | C5: 245122 | D5: USD millions | E5: reported | F5: identity | G5: Income Statements / Total revenue | H5: research/microsoft_fy2025/raw/official_report_excerpts.txt:21 (web L814)
A6: 2023 | B6: revenue | C6: 211915 | D6: USD millions | E6: reported | F6: identity | G6: Income Statements / Total revenue | H6: research/microsoft_fy2025/raw/official_report_excerpts.txt:21 (web L814)
A7: 2025 | B7: cogs | C7: 87831 | D7: USD millions | E7: reported | F7: identity | G7: Income Statements / Total cost of revenue | H7: research/microsoft_fy2025/raw/official_report_excerpts.txt:25 (web L818) | I7: Total cost of revenue includes service/cloud costs; COGS proxy for this model.
A8: 2024 | B8: cogs | C8: 74114 | D8: USD millions | E8: reported | F8: identity | G8: Income Statements / Total cost of revenue | H8: research/microsoft_fy2025/raw/official_report_excerpts.txt:25 (web L818) | I8: Total cost of revenue includes service/cloud costs; COGS proxy for this model.
A9: 2023 | B9: cogs | C9: 65863 | D9: USD millions | E9: reported | F9: identity | G9: Income Statements / Total cost of revenue | H9: research/microsoft_fy2025/raw/official_report_excerpts.txt:25 (web L818) | I9: Total cost of revenue includes service/cloud costs; COGS proxy for this model.
A10: 2025 | B10: gross_profit | C10: 193893 | D10: USD millions | E10: reported | F10: identity | G10: Income Statements / Gross margin | H10: research/microsoft_fy2025/raw/official_report_excerpts.txt:26 (web L819) | I10: Microsoft's monetary Gross margin line is gross profit, not a percentage.
A11: 2024 | B11: gross_profit | C11: 171008 | D11: USD millions | E11: reported | F11: identity | G11: Income Statements / Gross margin | H11: research/microsoft_fy2025/raw/official_report_excerpts.txt:26 (web L819) | I11: Microsoft's monetary Gross margin line is gross profit, not a percentage.
A12: 2023 | B12: gross_profit | C12: 146052 | D12: USD millions | E12: reported | F12: identity | G12: Income Statements / Gross margin | H12: research/microsoft_fy2025/raw/official_report_excerpts.txt:26 (web L819) | I12: Microsoft's monetary Gross margin line is gross profit, not a percentage.
A13: 2025 | B13: ebit | C13: 128528 | D13: USD millions | E13: reported | F13: identity | G13: Income Statements / Operating income | H13: research/microsoft_fy2025/raw/official_report_excerpts.txt:30 (web L823) | I13: Operating income is used as operating EBIT, not pretax income plus interest.
A14: 2024 | B14: ebit | C14: 109433 | D14: USD millions | E14: reported | F14: identity | G14: Income Statements / Operating income | H14: research/microsoft_fy2025/raw/official_report_excerpts.txt:30 (web L823) | I14: Operating income is used as operating EBIT, not pretax income plus interest.
A15: 2023 | B15: ebit | C15: 88523 | D15: USD millions | E15: reported | F15: identity | G15: Income Statements / Operating income | H15: research/microsoft_fy2025/raw/official_report_excerpts.txt:30 (web L823) | I15: Operating income is used as operating EBIT, not pretax income plus interest.
A16: 2025 | B16: income_tax_expense | C16: 21795 | D16: USD millions | E16: reported | F16: identity | G16: Income Statements / Provision for income taxes | H16: research/microsoft_fy2025/raw/official_report_excerpts.txt:33 (web L826)
A17: 2024 | B17: income_tax_expense | C17: 19651 | D17: USD millions | E17: reported | F17: identity | G17: Income Statements / Provision for income taxes | H17: research/microsoft_fy2025/raw/official_report_excerpts.txt:33 (web L826)
A18: 2023 | B18: income_tax_expense | C18: 16950 | D18: USD millions | E18: reported | F18: identity | G18: Income Statements / Provision for income taxes | H18: research/microsoft_fy2025/raw/official_report_excerpts.txt:33 (web L826)
A19: 2025 | B19: net_income | C19: 101832 | D19: USD millions | E19: reported | F19: identity | G19: Income Statements / Net income | H19: research/microsoft_fy2025/raw/official_report_excerpts.txt:34 (web L827)
A20: 2024 | B20: net_income | C20: 88136 | D20: USD millions | E20: reported | F20: identity | G20: Income Statements / Net income | H20: research/microsoft_fy2025/raw/official_report_excerpts.txt:34 (web L827)
A21: 2023 | B21: net_income | C21: 72361 | D21: USD millions | E21: reported | F21: identity | G21: Income Statements / Net income | H21: research/microsoft_fy2025/raw/official_report_excerpts.txt:34 (web L827)
A22: 2025 | B22: cash_flow_from_operations | C22: 136162 | D22: USD millions | E22: reported | F22: identity | G22: Cash Flows Statements / Net cash from operations | H22: research/microsoft_fy2025/raw/official_report_excerpts.txt:121 (web L910)
A23: 2024 | B23: cash_flow_from_operations | C23: 118548 | D23: USD millions | E23: reported | F23: identity | G23: Cash Flows Statements / Net cash from operations | H23: research/microsoft_fy2025/raw/official_report_excerpts.txt:121 (web L910)
A24: 2023 | B24: cash_flow_from_operations | C24: 87582 | D24: USD millions | E24: reported | F24: identity | G24: Cash Flows Statements / Net cash from operations | H24: research/microsoft_fy2025/raw/official_report_excerpts.txt:121 (web L910)
A25: 2025 | B25: capex | C25: 64551 | D25: USD millions | E25: reported | F25: negate reported cash outflow | G25: Cash Flows Statements / Additions to property and equipment | H25: research/microsoft_fy2025/raw/official_report_excerpts.txt:132 (web L921) | I25: Cash purchases of PP&E only; excludes noncash finance-lease additions, acquisitions and unpaid capex.
A26: 2024 | B26: capex | C26: 44477 | D26: USD millions | E26: reported | F26: negate reported cash outflow | G26: Cash Flows Statements / Additions to property and equipment | H26: research/microsoft_fy2025/raw/official_report_excerpts.txt:132 (web L921) | I26: Cash purchases of PP&E only; excludes noncash finance-lease additions, acquisitions and unpaid capex.
A27: 2023 | B27: capex | C27: 28107 | D27: USD millions | E27: reported | F27: negate reported cash outflow | G27: Cash Flows Statements / Additions to property and equipment | H27: research/microsoft_fy2025/raw/official_report_excerpts.txt:132 (web L921) | I27: Cash purchases of PP&E only; excludes noncash finance-lease additions, acquisitions and unpaid capex.
A28: 2025 | B28: dividends_paid | C28: 24082 | D28: USD millions | E28: reported | F28: negate reported cash outflow | G28: Cash Flows Statements / Common stock cash dividends paid | H28: research/microsoft_fy2025/raw/official_report_excerpts.txt:128 (web L917)
A29: 2024 | B29: dividends_paid | C29: 21771 | D29: USD millions | E29: reported | F29: negate reported cash outflow | G29: Cash Flows Statements / Common stock cash dividends paid | H29: research/microsoft_fy2025/raw/official_report_excerpts.txt:128 (web L917)
A30: 2023 | B30: dividends_paid | C30: 19800 | D30: USD millions | E30: reported | F30: negate reported cash outflow | G30: Cash Flows Statements / Common stock cash dividends paid | H30: research/microsoft_fy2025/raw/official_report_excerpts.txt:128 (web L917)
A31: 2025 | B31: cash_and_equivalents | C31: 30242 | D31: USD millions | E31: reported | F31: identity | G31: Cash Flows Statements / Cash and cash equivalents, end of period | H31: research/microsoft_fy2025/raw/official_report_excerpts.txt:142 (web L931) | I31: Excludes short-term investments, even though Microsoft also reports combined liquidity.
A32: 2024 | B32: cash_and_equivalents | C32: 18315 | D32: USD millions | E32: reported | F32: identity | G32: Cash Flows Statements / Cash and cash equivalents, end of period | H32: research/microsoft_fy2025/raw/official_report_excerpts.txt:142 (web L931) | I32: Excludes short-term investments, even though Microsoft also reports combined liquidity.
A33: 2023 | B33: cash_and_equivalents | C33: 34704 | D33: USD millions | E33: reported | F33: identity | G33: Cash Flows Statements / Cash and cash equivalents, end of period | H33: research/microsoft_fy2025/raw/official_report_excerpts.txt:142 (web L931) | I33: Excludes short-term investments, even though Microsoft also reports combined liquidity.
A34: 2025 | B34: interest_expense | C34: 2385 | D34: USD millions | E34: reported | F34: negate expense presentation | G34: Note 3 — Other Income (Expense), Net / Interest expense | H34: research/microsoft_fy2025/raw/official_report_excerpts.txt:172 (web L1132) | I34: Reported interest expense includes finance-lease interest and excludes capitalized interest; not cash interest paid.
A35: 2024 | B35: interest_expense | C35: 2935 | D35: USD millions | E35: reported | F35: negate expense presentation | G35: Note 3 — Other Income (Expense), Net / Interest expense | H35: research/microsoft_fy2025/raw/official_report_excerpts.txt:172 (web L1132) | I35: Reported interest expense includes finance-lease interest and excludes capitalized interest; not cash interest paid.
A36: 2023 | B36: interest_expense | C36: 1968 | D36: USD millions | E36: reported | F36: negate expense presentation | G36: Note 3 — Other Income (Expense), Net / Interest expense | H36: research/microsoft_fy2025/raw/official_report_excerpts.txt:172 (web L1132) | I36: Reported interest expense includes finance-lease interest and excludes capitalized interest; not cash interest paid.
A37: 2025 | B37: shares_outstanding | C37: 7434000000 | D37: shares | E37: reported | F37: millions of shares x 1,000,000 | G37: Note 15 — Shares Outstanding / Balance, end of year | H37: research/microsoft_fy2025/raw/official_report_excerpts.txt:298 (web L1734) | I37: FY-end shares, not weighted-average basic/diluted shares.
A38: 2024 | B38: shares_outstanding | C38: 7434000000 | D38: shares | E38: reported | F38: millions of shares x 1,000,000 | G38: Note 15 — Shares Outstanding / Balance, end of year | H38: research/microsoft_fy2025/raw/official_report_excerpts.txt:298 (web L1734) | I38: FY-end shares, not weighted-average basic/diluted shares.
A39: 2023 | B39: shares_outstanding | C39: 7432000000 | D39: shares | E39: reported | F39: millions of shares x 1,000,000 | G39: Note 15 — Shares Outstanding / Balance, end of year | H39: research/microsoft_fy2025/raw/official_report_excerpts.txt:298 (web L1734) | I39: FY-end shares, not weighted-average basic/diluted shares.
A40: 2025 | B40: total_assets | C40: 619003 | D40: USD millions | E40: reported | F40: identity | G40: Balance Sheets / Total assets | H40: research/microsoft_fy2025/raw/official_report_excerpts.txt:72 (web L864)
...

Sheet Derivations
A1: Recipe | B1: FY | C1: Value (absolute USD) | D1: Source / rounding / caveat
A2: operating-ebitda-separate-da-v1 | B2: 2023 | C2: 102023000000.0 | D2: {"recipe": "operating-ebitda-separate-da-v1", "fiscal_year": 2023, "note": "Approximate reconstructed operating EBITDA: operating EBIT + separately disclosed depreciation + intangible amortization; rounded source components. Not reported EBITDA; no extra ROU add-back.", "components": {"ebit": "88523000000", "ebit_sources": [{"source_file": "/Users/leonidpofa/VSCodeHruchevoPY/quant/Excel_automation/research/microsoft_fy2025/financials.csv", "source_sheet": null, "source_row": 2, "source_column": "ebit", "source_locator": "row 2, column ebit", "original_value": "88523", "original_unit": "millions", "candidate_id": null, "revision": null, "source_sha256": null}], "depreciation": {"value": "11.0", "unit": "billions", "label": "depreciation", "source_file": "research/microsoft_fy2025/raw/definition_notes_excerpts.txt", "source_sha256": "a6692b935a84d49b38c6fc1ba22169c52a093b0cb09251b6a59cb6773d4e66a9", "locator": {"file": "research/microsoft_fy2025/raw/definition_notes_excerpts.txt", "line": 53, "web_extracted_line": 1386}, "url": "https://www.microsoft.com/investor/reports/ar25/", "published_rounding": "0.1 billion USD"}, "intangible_amortization": {"value": "2.5", "unit": "billions", "label": "intangible_amortization", "source_file": "research/microsoft_fy2025/raw/official_report_excerpts.txt", "source_sha256": "639edbc6f0c3cc02cad90a481c9789d9e5c48814c7710462b22a635c4f517744", "locator": {"file": "research/microsoft_fy2025/raw/official_report_excerpts.txt", "line": 194, "web_extracted_line": 1476}, "url": "https://www.microsoft.com/investor/reports/ar25/", "published_rounding": "0.1 billion USD"}}}
A3: operating-ebitda-separate-da-v1 | B3: 2024 | C3: 129433000000.0 | D3: {"recipe": "operating-ebitda-separate-da-v1", "fiscal_year": 2024, "note": "Approximate reconstructed operating EBITDA: operating EBIT + separately disclosed depreciation + intangible amortization; rounded source components. Not reported EBITDA; no extra ROU add-back.", "components": {"ebit": "109433000000", "ebit_sources": [{"source_file": "/Users/leonidpofa/VSCodeHruchevoPY/quant/Excel_automation/research/microsoft_fy2025/financials.csv", "source_sheet": null, "source_row": 3, "source_column": "ebit", "source_locator": "row 3, column ebit", "original_value": "109433", "original_unit": "millions", "candidate_id": null, "revision": null, "source_sha256": null}], "depreciation": {"value": "15.2", "unit": "billions", "label": "depreciation", "source_file": "research/microsoft_fy2025/raw/definition_notes_excerpts.txt", "source_sha256": "a6692b935a84d49b38c6fc1ba22169c52a093b0cb09251b6a59cb6773d4e66a9", "locator": {"file": "research/microsoft_fy2025/raw/definition_notes_excerpts.txt", "line": 53, "web_extracted_line": 1386}, "url": "https://www.microsoft.com/investor/reports/ar25/", "published_rounding": "0.1 billion USD"}, "intangible_amortization": {"value": "4.8", "unit": "billions", "label": "intangible_amortization", "source_file": "research/microsoft_fy2025/raw/official_report_excerpts.txt", "source_sha256": "639edbc6f0c3cc02cad90a481c9789d9e5c48814c7710462b22a635c4f517744", "locator": {"file": "research/microsoft_fy2025/raw/official_report_excerpts.txt", "line": 194, "web_extracted_line": 1476}, "url": "https://www.microsoft.com/investor/reports/ar25/", "published_rounding": "0.1 billion USD"}}}
A4: operating-ebitda-separate-da-v1 | B4: 2025 | C4: 156528000000.0 | D4: {"recipe": "operating-ebitda-separate-da-v1", "fiscal_year": 2025, "note": "Approximate reconstructed operating EBITDA: operating EBIT + separately disclosed depreciation + intangible amortization; rounded source components. Not reported EBITDA; no extra ROU add-back.", "components": {"ebit": "128528000000", "ebit_sources": [{"source_file": "/Users/leonidpofa/VSCodeHruchevoPY/quant/Excel_automation/research/microsoft_fy2025/financials.csv", "source_sheet": null, "source_row": 4, "source_column": "ebit", "source_locator": "row 4, column ebit", "original_value": "128528", "original_unit": "millions", "candidate_id": null, "revision": null, "source_sha256": null}], "depreciation": {"value": "22.0", "unit": "billions", "label": "depreciation", "source_file": "research/microsoft_fy2025/raw/definition_notes_excerpts.txt", "source_sha256": "a6692b935a84d49b38c6fc1ba22169c52a093b0cb09251b6a59cb6773d4e66a9", "locator": {"file": "research/microsoft_fy2025/raw/definition_notes_excerpts.txt", "line": 53, "web_extracted_line": 1386}, "url": "https://www.microsoft.com/investor/reports/ar25/", "published_rounding": "0.1 billion USD"}, "intangible_amortization": {"value": "6.0", "unit": "billions", "label": "intangible_amortization", "source_file": "research/microsoft_fy2025/raw/official_report_excerpts.txt", "source_sha256": "639edbc6f0c3cc02cad90a481c9789d9e5c48814c7710462b22a635c4f517744", "locator": {"file": "research/microsoft_fy2025/raw/official_report_excerpts.txt", "line": 194, "web_extracted_line": 1476}, "url": "https://www.microsoft.com/investor/reports/ar25/", "published_rounding": "0.1 billion USD"}}}
